<?xml version="1.0" encoding="UTF-8"?>
<testng-results ignored="0" total="5" passed="2" failed="3" skipped="0">
  <reporter-output>
  </reporter-output>
  <suite started-at="2023-10-20T14:55:36 EDT" name="Suite" finished-at="2023-10-20T14:55:48 EDT" duration-ms="12892">
    <groups>
    </groups>
    <test started-at="2023-10-20T14:55:36 EDT" name="Test" finished-at="2023-10-20T14:55:48 EDT" duration-ms="12892">
      <class name="com.inetBanking.testCases.TC_Login_DataDrivenTesting_002">
        <test-method is-config="true" signature="setup(org.testng.ITestContext)[pri:0, instance:com.inetBanking.testCases.TC_Login_DataDrivenTesting_002@5be067de]" started-at="2023-10-20T14:55:36 EDT" name="setup" finished-at="2023-10-20T14:55:38 EDT" duration-ms="2537" status="PASS">
          <params>
            <param index="0">
              <value>
                <![CDATA[org.testng.TestRunner@147cc940]]>
              </value>
            </param>
          </params>
          <reporter-output>
          </reporter-output>
        </test-method> <!-- setup -->
        <test-method is-config="true" signature="testloading()[pri:0, instance:com.inetBanking.testCases.TC_Login_DataDrivenTesting_002@5be067de]" started-at="2023-10-20T14:55:38 EDT" name="testloading" finished-at="2023-10-20T14:55:38 EDT" duration-ms="1" status="PASS">
          <reporter-output>
          </reporter-output>
        </test-method> <!-- testloading -->
        <test-method signature="logintest(java.lang.String,java.lang.String)[pri:0, instance:com.inetBanking.testCases.TC_Login_DataDrivenTesting_002@5be067de]" started-at="2023-10-20T14:55:39 EDT" name="logintest" data-provider="dataProvider" finished-at="2023-10-20T14:55:42 EDT" duration-ms="3055" status="PASS">
          <params>
            <param index="0">
              <value>
                <![CDATA[mngr533282]]>
              </value>
            </param>
            <param index="1">
              <value>
                <![CDATA[UrAtyzE]]>
              </value>
            </param>
          </params>
          <reporter-output>
          </reporter-output>
        </test-method> <!-- logintest -->
        <test-method signature="logintest(java.lang.String,java.lang.String)[pri:0, instance:com.inetBanking.testCases.TC_Login_DataDrivenTesting_002@5be067de]" started-at="2023-10-20T14:55:42 EDT" name="logintest" data-provider="dataProvider" finished-at="2023-10-20T14:55:43 EDT" duration-ms="836" status="FAIL">
          <params>
            <param index="0">
              <value>
                <![CDATA[mngr533281]]>
              </value>
            </param>
            <param index="1">
              <value>
                <![CDATA[UrAtyzW]]>
              </value>
            </param>
          </params>
          <exception class="java.lang.AssertionError">
            <message>
              <![CDATA[expected [true] but found [false]]]>
            </message>
            <full-stacktrace>
              <![CDATA[java.lang.AssertionError: expected [true] but found [false]
at org.testng.Assert.fail(Assert.java:99)
at org.testng.Assert.failNotEquals(Assert.java:1037)
at org.testng.Assert.assertTrue(Assert.java:45)
at org.testng.Assert.assertTrue(Assert.java:55)
at com.inetBanking.testCases.TC_Login_DataDrivenTesting_002.logintest(TC_Login_DataDrivenTesting_002.java:72)
at java.base/jdk.internal.reflect.NativeMethodAccessorImpl.invoke0(Native Method)
at java.base/jdk.internal.reflect.NativeMethodAccessorImpl.invoke(NativeMethodAccessorImpl.java:62)
at java.base/jdk.internal.reflect.DelegatingMethodAccessorImpl.invoke(DelegatingMethodAccessorImpl.java:43)
at java.base/java.lang.reflect.Method.invoke(Method.java:566)
at org.testng.internal.MethodInvocationHelper.invokeMethod(MethodInvocationHelper.java:133)
at org.testng.internal.TestInvoker.invokeMethod(TestInvoker.java:598)
at org.testng.internal.TestInvoker.invokeTestMethod(TestInvoker.java:173)
at org.testng.internal.MethodRunner.runInSequence(MethodRunner.java:46)
at org.testng.internal.TestInvoker$MethodInvocationAgent.invoke(TestInvoker.java:824)
at org.testng.internal.TestInvoker.invokeTestMethods(TestInvoker.java:146)
at org.testng.internal.TestMethodWorker.invokeTestMethods(TestMethodWorker.java:146)
at org.testng.internal.TestMethodWorker.run(TestMethodWorker.java:128)
at java.base/java.util.ArrayList.forEach(ArrayList.java:1541)
at org.testng.TestRunner.privateRun(TestRunner.java:794)
at org.testng.TestRunner.run(TestRunner.java:596)
at org.testng.SuiteRunner.runTest(SuiteRunner.java:377)
at org.testng.SuiteRunner.runSequentially(SuiteRunner.java:371)
at org.testng.SuiteRunner.privateRun(SuiteRunner.java:332)
at org.testng.SuiteRunner.run(SuiteRunner.java:276)
at org.testng.SuiteRunnerWorker.runSuite(SuiteRunnerWorker.java:53)
at org.testng.SuiteRunnerWorker.run(SuiteRunnerWorker.java:96)
at org.testng.TestNG.runSuitesSequentially(TestNG.java:1212)
at org.testng.TestNG.runSuitesLocally(TestNG.java:1134)
at org.testng.TestNG.runSuites(TestNG.java:1063)
at org.testng.TestNG.run(TestNG.java:1031)
at org.testng.remote.AbstractRemoteTestNG.run(AbstractRemoteTestNG.java:115)
at org.testng.remote.RemoteTestNG.initAndRun(RemoteTestNG.java:251)
at org.testng.remote.RemoteTestNG.main(RemoteTestNG.java:77)
]]>
            </full-stacktrace>
          </exception> <!-- java.lang.AssertionError -->
          <reporter-output>
          </reporter-output>
        </test-method> <!-- logintest -->
        <test-method signature="logintest(java.lang.String,java.lang.String)[pri:0, instance:com.inetBanking.testCases.TC_Login_DataDrivenTesting_002@5be067de]" started-at="2023-10-20T14:55:43 EDT" name="logintest" data-provider="dataProvider" finished-at="2023-10-20T14:55:44 EDT" duration-ms="1389" status="FAIL">
          <params>
            <param index="0">
              <value>
                <![CDATA[mngr533283]]>
              </value>
            </param>
            <param index="1">
              <value>
                <![CDATA[UrAtyzQ]]>
              </value>
            </param>
          </params>
          <exception class="java.lang.AssertionError">
            <message>
              <![CDATA[expected [true] but found [false]]]>
            </message>
            <full-stacktrace>
              <![CDATA[java.lang.AssertionError: expected [true] but found [false]
at org.testng.Assert.fail(Assert.java:99)
at org.testng.Assert.failNotEquals(Assert.java:1037)
at org.testng.Assert.assertTrue(Assert.java:45)
at org.testng.Assert.assertTrue(Assert.java:55)
at com.inetBanking.testCases.TC_Login_DataDrivenTesting_002.logintest(TC_Login_DataDrivenTesting_002.java:72)
at java.base/jdk.internal.reflect.NativeMethodAccessorImpl.invoke0(Native Method)
at java.base/jdk.internal.reflect.NativeMethodAccessorImpl.invoke(NativeMethodAccessorImpl.java:62)
at java.base/jdk.internal.reflect.DelegatingMethodAccessorImpl.invoke(DelegatingMethodAccessorImpl.java:43)
at java.base/java.lang.reflect.Method.invoke(Method.java:566)
at org.testng.internal.MethodInvocationHelper.invokeMethod(MethodInvocationHelper.java:133)
at org.testng.internal.TestInvoker.invokeMethod(TestInvoker.java:598)
at org.testng.internal.TestInvoker.invokeTestMethod(TestInvoker.java:173)
at org.testng.internal.MethodRunner.runInSequence(MethodRunner.java:46)
at org.testng.internal.TestInvoker$MethodInvocationAgent.invoke(TestInvoker.java:824)
at org.testng.internal.TestInvoker.invokeTestMethods(TestInvoker.java:146)
at org.testng.internal.TestMethodWorker.invokeTestMethods(TestMethodWorker.java:146)
at org.testng.internal.TestMethodWorker.run(TestMethodWorker.java:128)
at java.base/java.util.ArrayList.forEach(ArrayList.java:1541)
at org.testng.TestRunner.privateRun(TestRunner.java:794)
at org.testng.TestRunner.run(TestRunner.java:596)
at org.testng.SuiteRunner.runTest(SuiteRunner.java:377)
at org.testng.SuiteRunner.runSequentially(SuiteRunner.java:371)
at org.testng.SuiteRunner.privateRun(SuiteRunner.java:332)
at org.testng.SuiteRunner.run(SuiteRunner.java:276)
at org.testng.SuiteRunnerWorker.runSuite(SuiteRunnerWorker.java:53)
at org.testng.SuiteRunnerWorker.run(SuiteRunnerWorker.java:96)
at org.testng.TestNG.runSuitesSequentially(TestNG.java:1212)
at org.testng.TestNG.runSuitesLocally(TestNG.java:1134)
at org.testng.TestNG.runSuites(TestNG.java:1063)
at org.testng.TestNG.run(TestNG.java:1031)
at org.testng.remote.AbstractRemoteTestNG.run(AbstractRemoteTestNG.java:115)
at org.testng.remote.RemoteTestNG.initAndRun(RemoteTestNG.java:251)
at org.testng.remote.RemoteTestNG.main(RemoteTestNG.java:77)
]]>
            </full-stacktrace>
          </exception> <!-- java.lang.AssertionError -->
          <reporter-output>
          </reporter-output>
        </test-method> <!-- logintest -->
        <test-method signature="logintest(java.lang.String,java.lang.String)[pri:0, instance:com.inetBanking.testCases.TC_Login_DataDrivenTesting_002@5be067de]" started-at="2023-10-20T14:55:45 EDT" name="logintest" data-provider="dataProvider" finished-at="2023-10-20T14:55:47 EDT" duration-ms="2227" status="PASS">
          <params>
            <param index="0">
              <value>
                <![CDATA[mngr533282]]>
              </value>
            </param>
            <param index="1">
              <value>
                <![CDATA[UrAtyzE]]>
              </value>
            </param>
          </params>
          <reporter-output>
          </reporter-output>
        </test-method> <!-- logintest -->
        <test-method signature="logintest(java.lang.String,java.lang.String)[pri:0, instance:com.inetBanking.testCases.TC_Login_DataDrivenTesting_002@5be067de]" started-at="2023-10-20T14:55:47 EDT" name="logintest" data-provider="dataProvider" finished-at="2023-10-20T14:55:48 EDT" duration-ms="1049" status="FAIL">
          <params>
            <param index="0">
              <value>
                <![CDATA[mngr533284]]>
              </value>
            </param>
            <param index="1">
              <value>
                <![CDATA[UrAtyzR]]>
              </value>
            </param>
          </params>
          <exception class="java.lang.AssertionError">
            <message>
              <![CDATA[expected [true] but found [false]]]>
            </message>
            <full-stacktrace>
              <![CDATA[java.lang.AssertionError: expected [true] but found [false]
at org.testng.Assert.fail(Assert.java:99)
at org.testng.Assert.failNotEquals(Assert.java:1037)
at org.testng.Assert.assertTrue(Assert.java:45)
at org.testng.Assert.assertTrue(Assert.java:55)
at com.inetBanking.testCases.TC_Login_DataDrivenTesting_002.logintest(TC_Login_DataDrivenTesting_002.java:72)
at java.base/jdk.internal.reflect.NativeMethodAccessorImpl.invoke0(Native Method)
at java.base/jdk.internal.reflect.NativeMethodAccessorImpl.invoke(NativeMethodAccessorImpl.java:62)
at java.base/jdk.internal.reflect.DelegatingMethodAccessorImpl.invoke(DelegatingMethodAccessorImpl.java:43)
at java.base/java.lang.reflect.Method.invoke(Method.java:566)
at org.testng.internal.MethodInvocationHelper.invokeMethod(MethodInvocationHelper.java:133)
at org.testng.internal.TestInvoker.invokeMethod(TestInvoker.java:598)
at org.testng.internal.TestInvoker.invokeTestMethod(TestInvoker.java:173)
at org.testng.internal.MethodRunner.runInSequence(MethodRunner.java:46)
at org.testng.internal.TestInvoker$MethodInvocationAgent.invoke(TestInvoker.java:824)
at org.testng.internal.TestInvoker.invokeTestMethods(TestInvoker.java:146)
at org.testng.internal.TestMethodWorker.invokeTestMethods(TestMethodWorker.java:146)
at org.testng.internal.TestMethodWorker.run(TestMethodWorker.java:128)
at java.base/java.util.ArrayList.forEach(ArrayList.java:1541)
at org.testng.TestRunner.privateRun(TestRunner.java:794)
at org.testng.TestRunner.run(TestRunner.java:596)
at org.testng.SuiteRunner.runTest(SuiteRunner.java:377)
at org.testng.SuiteRunner.runSequentially(SuiteRunner.java:371)
at org.testng.SuiteRunner.privateRun(SuiteRunner.java:332)
at org.testng.SuiteRunner.run(SuiteRunner.java:276)
at org.testng.SuiteRunnerWorker.runSuite(SuiteRunnerWorker.java:53)
at org.testng.SuiteRunnerWorker.run(SuiteRunnerWorker.java:96)
at org.testng.TestNG.runSuitesSequentially(TestNG.java:1212)
at org.testng.TestNG.runSuitesLocally(TestNG.java:1134)
at org.testng.TestNG.runSuites(TestNG.java:1063)
at org.testng.TestNG.run(TestNG.java:1031)
at org.testng.remote.AbstractRemoteTestNG.run(AbstractRemoteTestNG.java:115)
at org.testng.remote.RemoteTestNG.initAndRun(RemoteTestNG.java:251)
at org.testng.remote.RemoteTestNG.main(RemoteTestNG.java:77)
]]>
            </full-stacktrace>
          </exception> <!-- java.lang.AssertionError -->
          <reporter-output>
          </reporter-output>
        </test-method> <!-- logintest -->
        <test-method is-config="true" signature="tearDown()[pri:0, instance:com.inetBanking.testCases.TC_Login_DataDrivenTesting_002@5be067de]" started-at="2023-10-20T14:55:48 EDT" name="tearDown" finished-at="2023-10-20T14:55:48 EDT" duration-ms="191" status="PASS">
          <reporter-output>
          </reporter-output>
        </test-method> <!-- tearDown -->
      </class> <!-- com.inetBanking.testCases.TC_Login_DataDrivenTesting_002 -->
    </test> <!-- Test -->
  </suite> <!-- Suite -->
</testng-results>
